<pre>--- Summary ---
Tests passed: 0 out of 4

--- Details ---
Test #0: failed 
Test case description: ML4T-220
Traceback:
  File "grade_strategy_learner.py", line 237, in test_strategy
    ) = run_with_timeout(timeoutwrapper_strategylearner, max_time, (), {})
  File "grading.py", line 168, in run_with_timeout
    if not ("output" in rv_dict):
  File "<string>", line 2, in __contains_
  File "managers.py", line 753, in _callmethod
    self._connect()
  File "managers.py", line 740, in _connect
    conn = self._Client(self._token.address, authkey=self._authkey)
  File "connection.py", line 487, in Client
    c = SocketClient(address)
  File "connection.py", line 614, in SocketClient
    s.connect(address)
ConnectionRefusedError: [Errno 111] Connection refused

Test #1: failed 
Test case description: AAPL
Traceback:
  File "grade_strategy_learner.py", line 237, in test_strategy
    ) = run_with_timeout(timeoutwrapper_strategylearner, max_time, (), {})
  File "grading.py", line 159, in run_with_timeout
    rv_dict = timeout_manager.dict()
  File "managers.py", line 662, in temp
    token, exp = self._create(typeid, *args, **kwds)
  File "managers.py", line 554, in _create
    conn = self._Client(self._address, authkey=self._authkey)
  File "connection.py", line 487, in Client
    c = SocketClient(address)
  File "connection.py", line 614, in SocketClient
    s.connect(address)
ConnectionRefusedError: [Errno 111] Connection refused

Test #2: failed 
Test case description: SINE_FAST_NOISE
Traceback:
  File "grade_strategy_learner.py", line 237, in test_strategy
    ) = run_with_timeout(timeoutwrapper_strategylearner, max_time, (), {})
  File "grading.py", line 159, in run_with_timeout
    rv_dict = timeout_manager.dict()
  File "managers.py", line 662, in temp
    token, exp = self._create(typeid, *args, **kwds)
  File "managers.py", line 554, in _create
    conn = self._Client(self._address, authkey=self._authkey)
  File "connection.py", line 487, in Client
    c = SocketClient(address)
  File "connection.py", line 614, in SocketClient
    s.connect(address)
ConnectionRefusedError: [Errno 111] Connection refused

Test #3: failed 
Test case description: UNH - In sample
Traceback:
  File "grade_strategy_learner.py", line 237, in test_strategy
    ) = run_with_timeout(timeoutwrapper_strategylearner, max_time, (), {})
  File "grading.py", line 159, in run_with_timeout
    rv_dict = timeout_manager.dict()
  File "managers.py", line 662, in temp
    token, exp = self._create(typeid, *args, **kwds)
  File "managers.py", line 554, in _create
    conn = self._Client(self._address, authkey=self._authkey)
  File "connection.py", line 487, in Client
    c = SocketClient(address)
  File "connection.py", line 614, in SocketClient
    s.connect(address)
ConnectionRefusedError: [Errno 111] Connection refused

</pre>
